{
    "url": "https://api.github.com/repos/spack/spack/issues/17405",
    "repository_url": "https://api.github.com/repos/spack/spack",
    "labels_url": "https://api.github.com/repos/spack/spack/issues/17405/labels{/name}",
    "comments_url": "https://api.github.com/repos/spack/spack/issues/17405/comments",
    "events_url": "https://api.github.com/repos/spack/spack/issues/17405/events",
    "html_url": "https://github.com/spack/spack/issues/17405",
    "id": 652262471,
    "node_id": "MDU6SXNzdWU2NTIyNjI0NzE=",
    "number": 17405,
    "title": "The fixture \"mock_gnupghome\" fails at times during cleanup",
    "user": {
        "login": "alalazo",
        "id": 4199709,
        "node_id": "MDQ6VXNlcjQxOTk3MDk=",
        "avatar_url": "https://avatars.githubusercontent.com/u/4199709?v=4",
        "gravatar_id": "",
        "url": "https://api.github.com/users/alalazo",
        "html_url": "https://github.com/alalazo",
        "followers_url": "https://api.github.com/users/alalazo/followers",
        "following_url": "https://api.github.com/users/alalazo/following{/other_user}",
        "gists_url": "https://api.github.com/users/alalazo/gists{/gist_id}",
        "starred_url": "https://api.github.com/users/alalazo/starred{/owner}{/repo}",
        "subscriptions_url": "https://api.github.com/users/alalazo/subscriptions",
        "organizations_url": "https://api.github.com/users/alalazo/orgs",
        "repos_url": "https://api.github.com/users/alalazo/repos",
        "events_url": "https://api.github.com/users/alalazo/events{/privacy}",
        "received_events_url": "https://api.github.com/users/alalazo/received_events",
        "type": "User",
        "site_admin": false
    },
    "labels": [
        {
            "id": 73908754,
            "node_id": "MDU6TGFiZWw3MzkwODc1NA==",
            "url": "https://api.github.com/repos/spack/spack/labels/bug",
            "name": "bug",
            "color": "fc2929",
            "default": true,
            "description": null
        },
        {
            "id": 1491155556,
            "node_id": "MDU6TGFiZWwxNDkxMTU1NTU2",
            "url": "https://api.github.com/repos/spack/spack/labels/ci",
            "name": "ci",
            "color": "9891e0",
            "default": false,
            "description": "Issues related to Continuous Integration"
        },
        {
            "id": 512483297,
            "node_id": "MDU6TGFiZWw1MTI0ODMyOTc=",
            "url": "https://api.github.com/repos/spack/spack/labels/impact-low",
            "name": "impact-low",
            "color": "fef2c0",
            "default": false,
            "description": ""
        },
        {
            "id": 456341797,
            "node_id": "MDU6TGFiZWw0NTYzNDE3OTc=",
            "url": "https://api.github.com/repos/spack/spack/labels/tests",
            "name": "tests",
            "color": "b60205",
            "default": false,
            "description": "General test capability(ies)"
        }
    ],
    "state": "open",
    "locked": false,
    "assignee": null,
    "assignees": [],
    "milestone": null,
    "comments": 0,
    "created_at": "2020-07-07T11:56:51Z",
    "updated_at": "2020-07-07T11:56:51Z",
    "closed_at": null,
    "author_association": "MEMBER",
    "active_lock_reason": null,
    "body": "Recently there have been a few CI jobs failing at times during the cleanup phase of the `mock_gnupghome` fixture. An example of a job that failed in that way is:\r\n- https://github.com/spack/spack/runs/842564816\r\n\r\n\r\n### Steps to reproduce the issue\r\n\r\nThe error occurs sporadically during our CI jobs on Github.\r\n\r\n\r\n### Error Message\r\n\r\nThe relevant part of the error message is:\r\n```\r\n[ ... ]\r\n        # clean up, since we are doing this manually\r\n>       shutil.rmtree(short_name_tmpdir)\r\n\r\nlib/spack/spack/test/conftest.py:786:\r\n_ _ _ _ _ _ _ _ _ _ _ _ _ _ _ _ _ _ _ _ _ _ _ _ _ _ _ _ _ _ _ _ _ _ _ _ _ _ _ _ \r\n/opt/hostedtoolcache/Python/3.5.9/x64/lib/python3.5/shutil.py:480: in rmtree\r\n    _rmtree_safe_fd(fd, path, onerror)\r\n/opt/hostedtoolcache/Python/3.5.9/x64/lib/python3.5/shutil.py:438: in _rmtree_safe_fd\r\n    onerror(os.unlink, fullname, sys.exc_info())\r\n_ _ _ _ _ _ _ _ _ _ _ _ _ _ _ _ _ _ _ _ _ _ _ _ _ _ _ _ _ _ _ _ _ _ _ _ _ _ _ _ \r\n\r\n[ ... ]\r\n```\r\n\r\n### Information on your system\r\n```\r\nCurrent runner version: '2.263.0'\r\nOperating System\r\n  Ubuntu\r\n  18.04.4\r\n  LTS\r\nVirtual Environment\r\n  Environment: ubuntu-18.04\r\n  Version: 20200625.0\r\n  Included Software: https://github.com/actions/virtual-environments/blob/ubuntu18/20200625.0/images/linux/Ubuntu1804-README.md\r\n[ ... ]\r\nSuccessfully setup CPython (3.5.9)\r\n```\r\n\r\n### Additional information\r\n\r\n<!-- These boxes can be checked by replacing [ ] with [x] or by clicking them after submitting the issue. -->\r\n- [ ] I have run `spack debug report` and reported the version of Spack/Python/Platform\r\n- [x] I have searched the issues of this repo and believe this is not a duplicate\r\n- [x] I have run the failing commands in debug mode and reported the output\r\n",
    "performed_via_github_app": null
}